<mujoco model="go1 scene">
  <compiler angle="radian" meshdir="../assets/"/>

  <option timestep="0.004" iterations="1" ls_iterations="5">
    <flag eulerdamp="disable"/>
  </option>

  <size nkey="5"/>

  <visual>
    <global azimuth="120" elevation="-20"/>
    <quality shadowsize="8192"/>
    <headlight ambient="0.2 0.2 0.2" diffuse="0.8 0.8 0.8" specular="1 1 1"/>
    <map force="0.01"/>
    <scale forcewidth="0.3" contactwidth="0.5" contactheight="0.2"/>
    <rgba force="1 0 0 1"/>
  </visual>

  <statistic meansize="0.04" extent="0.8" center="0 0 0.1"/>

  <default>
    <default class="go1">
      <joint armature="0.005" damping="0.5"/>
      <geom condim="1"/>
      <general forcerange="-23.7 23.7" biastype="affine" gainprm="35" biasprm="0 -35"/>
      <default class="abduction">
        <joint range="-0.863 0.863" frictionloss="0.3"/>
      </default>
      <default class="hip">
        <joint range="-0.686 4.501" frictionloss="0.3"/>
      </default>
      <default class="knee">
        <joint range="-2.818 -0.888" frictionloss="1"/>
        <general forcerange="-35.55 35.55"/>
      </default>
      <default class="visual">
        <geom type="mesh" contype="0" conaffinity="0" group="2" material="dark"/>
      </default>
      <default class="collision">
        <geom type="capsule" group="3"/>
        <default class="hip_left1">
          <geom size="0.046 0.02 0" type="cylinder"/>
        </default>
        <default class="hip_left2">
          <geom size="0.031 0.02 0" type="cylinder"/>
        </default>
        <default class="hip_left3">
          <geom size="0.046 0.02 0" type="cylinder"/>
        </default>
        <default class="hip_right1">
          <geom size="0.046 0.02 0" type="cylinder"/>
        </default>
        <default class="hip_right2">
          <geom size="0.031 0.02 0" type="cylinder"/>
        </default>
        <default class="hip_right3">
          <geom size="0.046 0.02 0" type="cylinder"/>
        </default>
        <default class="thigh1">
          <geom size="0.015 0 0"/>
        </default>
        <default class="thigh2">
          <geom size="0.015 0 0"/>
        </default>
        <default class="thigh3">
          <geom size="0.015 0 0"/>
        </default>
        <default class="calf1">
          <geom size="0.01 0 0"/>
        </default>
        <default class="calf2">
          <geom size="0.01 0 0"/>
        </default>
        <default class="foot">
          <geom size="0.023 0 0" type="sphere" condim="3" solimp="0.9 0.95 0.023"/>
        </default>
      </default>
    </default>
  </default>

  <custom>
    <numeric name="max_contact_points" size="1" data="30"/>
    <numeric name="max_geom_pairs" size="1" data="12"/>
  </custom>

  <asset>
    <texture type="skybox" builtin="gradient" rgb1="1 1 1" rgb2="1 1 1" width="800" height="4800"/>
    <texture type="2d" name="groundplane" builtin="checker" mark="edge" rgb1="1 1 1" rgb2="1 1 1" width="300" height="300"/>
    <material name="dark" rgba="0.2 0.2 0.2 1"/>
    <material name="groundplane" texture="groundplane" texuniform="true" texrepeat="5 5"/>
    <mesh name="trunk" class="go1" content_type="model/stl" file="trunk.stl"/>
    <mesh name="hip" class="go1" content_type="model/stl" file="hip.stl"/>
    <mesh name="thigh_mirror" class="go1" content_type="model/stl" file="thigh_mirror.stl"/>
    <mesh name="calf" class="go1" content_type="model/stl" file="calf.stl"/>
    <mesh name="thigh" class="go1" content_type="model/stl" file="thigh.stl"/>
  </asset>

  <worldbody>
    <geom name="floor" size="0 0 0.01" type="plane" conaffinity="0" priority="1" friction="0.6" material="groundplane"/>
    <light name="spotlight" target="trunk" pos="3 0 4" dir="0 0 -1" mode="targetbodycom"/>
    <body name="trunk" childclass="go1" pos="0 0 0.445">
      <inertial pos="0.0223 0.002 -0.0005" quat="-0.00342088 0.705204 0.000106698 0.708996" mass="5.204" diaginertia="0.0716565 0.0630105 0.0168101"/>
      <joint type="free" limited="false" actuatorfrclimited="false" armature="0" damping="0"/>
      <geom class="visual" mesh="trunk"/>
      <geom class="collision" size="0.058 0.125" pos="0 -0.04 0" quat="0.707107 0 0.707107 0" type="cylinder"/>
      <geom class="collision" size="0.058 0.125" pos="0 0.04 0" quat="0.707107 0 0.707107 0" type="cylinder"/>
      <site name="head" pos="0.3 0 0" size="0.02" group="5" rgba="1 0 0 1"/>
      <site name="imu" pos="-0.01592 -0.06659 -0.00617" group="5"/>
      <camera name="track" pos="0.846 -1.3 0.316" quat="0.791164 0.554139 0.148485 0.211997" mode="trackcom"/>
      <camera name="top" pos="-1 0 1" quat="0.653281 0.270598 -0.270598 -0.653281" mode="trackcom"/>
      <camera name="side" pos="0 -1 0.3" quat="0.850651 0.525731 0 0" mode="trackcom"/>
      <camera name="back" pos="-1 0 0.3" quat="0.601501 0.371748 -0.371748 -0.601501" mode="trackcom"/>
      <body name="FR_hip" pos="0.1881 -0.04675 0">
        <inertial pos="-0.0049166 0.00762615 -8.865e-05" quat="0.507341 0.514169 0.495027 0.482891" mass="0.68" diaginertia="0.000734064 0.000468438 0.000398719"/>
        <joint name="FR_hip_joint" class="abduction" pos="0 0 0" axis="1 0 0"/>
        <geom class="visual" mesh="hip"/>
        <geom name="fr_hip" class="hip_right1" pos="0 -0.045 0" quat="0.707107 0.707107 0 0"/>
        <body name="FR_thigh" pos="0 -0.08 0">
          <inertial pos="-0.00304722 0.019315 -0.0305004" quat="0.65243 -0.0272313 0.0775126 0.753383" mass="1.009" diaginertia="0.00478717 0.00460903 0.000709268"/>
          <joint name="FR_thigh_joint" class="hip" pos="0 0 0" axis="0 1 0"/>
          <geom class="visual" mesh="thigh_mirror"/>
          <geom name="fr_thigh1" class="thigh1" size="0.015 0.08" pos="-0.02 0 -0.08"/>
          <geom name="fr_thigh2" class="thigh2" size="0.015 0.0509902" pos="-0.01 0 -0.05" quat="0.995133 0 0.0985376 0"/>
          <geom name="fr_thigh3" class="thigh3" size="0.015 0.0223607" pos="-0.01 0 -0.18" quat="0.973249 0 -0.229753 0"/>
          <body name="FR_calf" pos="0 0 -0.213">
            <inertial pos="0.00429862 0.000976676 -0.146197" quat="0.691246 0.00357467 0.00511118 0.722592" mass="0.195862" diaginertia="0.00149767 0.00148468 3.58427e-05"/>
            <joint name="FR_calf_joint" class="knee" pos="0 0 0" axis="0 1 0"/>
            <geom class="visual" mesh="calf"/>
            <geom name="fr_calf1" class="calf1" size="0.01 0.0657647" pos="0.01 0 -0.065" quat="0.997089 0 -0.0762506 0"/>
            <geom name="fr_calf2" class="calf2" size="0.01 0.0364005" pos="0.01 0 -0.165" quat="0.990334 0 0.138701 0"/>
            <geom name="FR" class="foot" pos="0 0 -0.213"/>
            <site name="FR" pos="0 0 -0.213" size="0.023" group="5"/>
          </body>
        </body>
      </body>
      <body name="FL_hip" pos="0.1881 0.04675 0">
        <inertial pos="-0.0049166 -0.00762615 -8.865e-05" quat="0.482891 0.495027 0.514169 0.507341" mass="0.68" diaginertia="0.000734064 0.000468438 0.000398719"/>
        <joint name="FL_hip_joint" class="abduction" pos="0 0 0" axis="1 0 0"/>
        <geom class="visual" mesh="hip"/>
        <geom name="fl_hip" class="hip_left1" pos="0 0.045 0" quat="0.707107 0.707107 0 0"/>
        <body name="FL_thigh" pos="0 0.08 0">
          <inertial pos="-0.00304722 -0.019315 -0.0305004" quat="0.753383 0.0775126 -0.0272313 0.65243" mass="1.009" diaginertia="0.00478717 0.00460903 0.000709268"/>
          <joint name="FL_thigh_joint" class="hip" pos="0 0 0" axis="0 1 0"/>
          <geom class="visual" mesh="thigh"/>
          <geom name="fl_thigh1" class="thigh1" size="0.015 0.08" pos="-0.02 0 -0.08"/>
          <geom name="fl_thigh2" class="thigh2" size="0.015 0.0509902" pos="-0.01 0 -0.05" quat="0.995133 0 0.0985376 0"/>
          <geom name="fl_thigh3" class="thigh3" size="0.015 0.0223607" pos="-0.01 0 -0.18" quat="0.973249 0 -0.229753 0"/>
          <body name="FL_calf" pos="0 0 -0.213">
            <inertial pos="0.00429862 0.000976676 -0.146197" quat="0.691246 0.00357467 0.00511118 0.722592" mass="0.195862" diaginertia="0.00149767 0.00148468 3.58427e-05"/>
            <joint name="FL_calf_joint" class="knee" pos="0 0 0" axis="0 1 0"/>
            <geom class="visual" mesh="calf"/>
            <geom name="fl_calf1" class="calf1" size="0.01 0.0657647" pos="0.01 0 -0.065" quat="0.997089 0 -0.0762506 0"/>
            <geom name="fl_calf2" class="calf2" size="0.01 0.0364005" pos="0.01 0 -0.165" quat="0.990334 0 0.138701 0"/>
            <geom name="FL" class="foot" pos="0 0 -0.213"/>
            <site name="FL" pos="0 0 -0.213" size="0.023" group="5"/>
          </body>
        </body>
      </body>
      <body name="RR_hip" pos="-0.1881 -0.04675 0">
        <inertial pos="0.0049166 0.00762615 -8.865e-05" quat="0.495027 0.482891 0.507341 0.514169" mass="0.68" diaginertia="0.000734064 0.000468438 0.000398719"/>
        <joint name="RR_hip_joint" class="abduction" pos="0 0 0" axis="1 0 0"/>
        <geom class="visual" quat="0 0 0 -1" mesh="hip"/>
        <geom name="rr_hip" class="hip_right1" pos="0 -0.045 0" quat="0.707107 0.707107 0 0"/>
        <body name="RR_thigh" pos="0 -0.08 0">
          <inertial pos="-0.00304722 0.019315 -0.0305004" quat="0.65243 -0.0272313 0.0775126 0.753383" mass="1.009" diaginertia="0.00478717 0.00460903 0.000709268"/>
          <joint name="RR_thigh_joint" class="hip" pos="0 0 0" axis="0 1 0"/>
          <geom class="visual" mesh="thigh_mirror"/>
          <geom name="rr_thigh1" class="thigh1" size="0.015 0.08" pos="-0.02 0 -0.08"/>
          <geom name="rr_thigh2" class="thigh2" size="0.015 0.0509902" pos="-0.01 0 -0.05" quat="0.995133 0 0.0985376 0"/>
          <geom name="rr_thigh3" class="thigh3" size="0.015 0.0223607" pos="-0.01 0 -0.18" quat="0.973249 0 -0.229753 0"/>
          <body name="RR_calf" pos="0 0 -0.213">
            <inertial pos="0.00429862 0.000976676 -0.146197" quat="0.691246 0.00357467 0.00511118 0.722592" mass="0.195862" diaginertia="0.00149767 0.00148468 3.58427e-05"/>
            <joint name="RR_calf_joint" class="knee" pos="0 0 0" axis="0 1 0"/>
            <geom class="visual" mesh="calf"/>
            <geom name="rr_calf1" class="calf1" size="0.01 0.0657647" pos="0.01 0 -0.065" quat="0.997089 0 -0.0762506 0"/>
            <geom name="rr_calf2" class="calf2" size="0.01 0.0364005" pos="0.01 0 -0.165" quat="0.990334 0 0.138701 0"/>
            <geom name="RR" class="foot" pos="0 0 -0.213"/>
            <site name="RR" pos="0 0 -0.213" size="0.023" group="5"/>
          </body>
        </body>
      </body>
      <body name="RL_hip" pos="-0.1881 0.04675 0">
        <inertial pos="0.0049166 -0.00762615 -8.865e-05" quat="0.514169 0.507341 0.482891 0.495027" mass="0.68" diaginertia="0.000734064 0.000468438 0.000398719"/>
        <joint name="RL_hip_joint" class="abduction" pos="0 0 0" axis="1 0 0"/>
        <geom class="visual" quat="0 0 1 0" mesh="hip"/>
        <geom name="rl_hip" class="hip_left1" pos="0 0.045 0" quat="0.707107 0.707107 0 0"/>
        <body name="RL_thigh" pos="0 0.08 0">
          <inertial pos="-0.00304722 -0.019315 -0.0305004" quat="0.753383 0.0775126 -0.0272313 0.65243" mass="1.009" diaginertia="0.00478717 0.00460903 0.000709268"/>
          <joint name="RL_thigh_joint" class="hip" pos="0 0 0" axis="0 1 0"/>
          <geom class="visual" mesh="thigh"/>
          <geom name="rl_thigh1" class="thigh1" size="0.015 0.08" pos="-0.02 0 -0.08"/>
          <geom name="rl_thigh2" class="thigh2" size="0.015 0.0509902" pos="-0.01 0 -0.05" quat="0.995133 0 0.0985376 0"/>
          <geom name="rl_thigh3" class="thigh3" size="0.015 0.0223607" pos="-0.01 0 -0.18" quat="0.973249 0 -0.229753 0"/>
          <body name="RL_calf" pos="0 0 -0.213">
            <inertial pos="0.00429862 0.000976676 -0.146197" quat="0.691246 0.00357467 0.00511118 0.722592" mass="0.195862" diaginertia="0.00149767 0.00148468 3.58427e-05"/>
            <joint name="RL_calf_joint" class="knee" pos="0 0 0" axis="0 1 0"/>
            <geom class="visual" mesh="calf"/>
            <geom name="rl_calf1" class="calf1" size="0.01 0.0657647" pos="0.01 0 -0.065" quat="0.997089 0 -0.0762506 0"/>
            <geom name="rl_calf2" class="calf2" size="0.01 0.0364005" pos="0.01 0 -0.165" quat="0.990334 0 0.138701 0"/>
            <geom name="RL" class="foot" pos="0 0 -0.213"/>
            <site name="RL" pos="0 0 -0.213" size="0.023" group="5"/>
          </body>
        </body>
      </body>
    </body>
  </worldbody>

  <actuator>
    <general name="FR_hip" class="abduction" joint="FR_hip_joint" ctrlrange="-0.863 0.863"/>
    <general name="FR_thigh" class="hip" joint="FR_thigh_joint" ctrlrange="-0.686 4.501"/>
    <general name="FR_calf" class="knee" joint="FR_calf_joint" ctrlrange="-2.818 -0.888"/>
    <general name="FL_hip" class="abduction" joint="FL_hip_joint" ctrlrange="-0.863 0.863"/>
    <general name="FL_thigh" class="hip" joint="FL_thigh_joint" ctrlrange="-0.686 4.501"/>
    <general name="FL_calf" class="knee" joint="FL_calf_joint" ctrlrange="-2.818 -0.888"/>
    <general name="RR_hip" class="abduction" joint="RR_hip_joint" ctrlrange="-0.863 0.863"/>
    <general name="RR_thigh" class="hip" joint="RR_thigh_joint" ctrlrange="-0.686 4.501"/>
    <general name="RR_calf" class="knee" joint="RR_calf_joint" ctrlrange="-2.818 -0.888"/>
    <general name="RL_hip" class="abduction" joint="RL_hip_joint" ctrlrange="-0.863 0.863"/>
    <general name="RL_thigh" class="hip" joint="RL_thigh_joint" ctrlrange="-0.686 4.501"/>
    <general name="RL_calf" class="knee" joint="RL_calf_joint" ctrlrange="-2.818 -0.888"/>
  </actuator>

  <sensor>
    <gyro site="imu" name="gyro"/>
    <velocimeter site="imu" name="local_linvel"/>
    <accelerometer site="imu" name="accelerometer"/>
    <framepos objtype="site" objname="imu" name="position"/>
    <framezaxis objtype="site" objname="imu" name="upvector"/>
    <framexaxis objtype="site" objname="imu" name="forwardvector"/>
    <framelinvel objtype="site" objname="imu" name="global_linvel"/>
    <frameangvel objtype="site" objname="imu" name="global_angvel"/>
    <framequat objtype="site" objname="imu" name="orientation"/>
    <framelinvel objtype="site" objname="FR" name="FR_global_linvel"/>
    <framelinvel objtype="site" objname="FL" name="FL_global_linvel"/>
    <framelinvel objtype="site" objname="RR" name="RR_global_linvel"/>
    <framelinvel objtype="site" objname="RL" name="RL_global_linvel"/>
    <framepos objtype="site" objname="FR" reftype="site" refname="imu" name="FR_pos"/>
    <framepos objtype="site" objname="FL" reftype="site" refname="imu" name="FL_pos"/>
    <framepos objtype="site" objname="RR" reftype="site" refname="imu" name="RR_pos"/>
    <framepos objtype="site" objname="RL" reftype="site" refname="imu" name="RL_pos"/>
    <framepos objtype="site" objname="head" name="head_pos"/>
  </sensor>

  <keyframe>
    <key name="home" qpos="0 0 0.278 1 0 0 0 0.1 0.9 -1.8 -0.1 0.9 -1.8 0.1 0.9 -1.8 -0.1 0.9 -1.8" ctrl="0.1 0.9 -1.8 -0.1 0.9 -1.8 0.1 0.9 -1.8 -0.1 0.9 -1.8"/>
    <key name="home_higher" qpos="0 0 0.31 1 0 0 0 0 0.82 -1.63 0 0.82 -1.63 0 0.82 -1.63 0 0.82 -1.63" ctrl="0 0.82 -1.63 0 0.82 -1.63 0 0.82 -1.63 0 0.82 -1.63"/>
    <key name="pre_recovery" qpos="-0.0318481 -0.000215369 0.0579031 1 -2.70738e-05 6.06169e-05 0.000231261 -0.352275 1.18554 -2.80738 0.360892 1.1806 -2.80281 -0.381197 1.16812 -2.79123 0.391054 1.1622 -2.78576" ctrl="-0.352275 1.18554 -2.80738 0.360892 1.1806 -2.80281 -0.381197 1.16812 -2.79123 0.391054 1.1622 -2.78576"/>
    <key name="footstand" qpos="0 0 0.54 0.707107 0 -0.707107 0 0 0.82 -1.6 0 0.82 -1.68 0 1.82 -1.16 0 1.82 -1.16" ctrl="0 0.82 -1.6 0 0.82 -1.68 0 1.82 -1.16 0 1.82 -1.16"/>
    <key name="handstand" qpos="0 0 0.54 0.707107 0 0.707107 0 0 -0.686 -1.16 0 -0.686 -1.16 0 1.7 -1.853 0 1.7 -1.853" ctrl="0 -0.686 -1.16 0 -0.686 -1.16 0 1.7 -1.853 0 1.7 -1.853"/>
  </keyframe>
</mujoco>
